# CHAP 47 - 에러 처리

## 에러 처리의 필요성

- 발생한 에러에 대해 대처하지 않고 방치하면 프로그램은 강제 종료된다.
- 우리가 작성한 코드에서는 언제나 에러나 예외적인 상황이 발생할 수 있으므로 이에 대응하는 코드를 작성하는 것이 중요하다.

## try … catch … finally 문

```jsx
console.log('[Start]');

try {
  // 실행할 코드(에러가 발생할 가능성이 있는 코드)
  foo();
} catch (err) {
  // try 코드 블록에서 에러가 발생하면 이 코드 블록의 코드가 실행된다.
  // err에는 try 코드 블록에서 발생한 Error 객체가 전달된다.
  console.error(err); // ReferenceError: foo is not defined
} finally {
  // 에러 발생과 상관없이 반드시 한 번 실행된다.
  console.log('finally');
}

// try...catch...finally 문으로 에러를 처리하면 프로그램이 강제 종료되지 않는다.
console.log('[End]');
```

- 먼저 try 코드 블록이 실행한다. 이때 에러가 발생하면 catch문의 err변수에 전달되고 catch 코드 블록이 실행된다.
- catch문의 err변수는 try 코드 블록에 포함된 문 중에서 에러가 발생하면 생성되고 catch 코드 블록에서만 유효하다.
- 이를 이용하면 프로그램이 강제 종료되지 않는다.

## Error 객체

```jsx
const error = new Error('invalid');
```

- Error 생성자 함수는 에러 객체를 생성한다.
- 에러를 상세히 설명하는 에러 메시지를 인수로 전달할 수 있다.
- message, stack 프로퍼티를 갖는다.
- message 프로퍼티: Error 생성자 함수에 인수로 전달한 에러 메시지
- stack 프로퍼티: 에러를 발생시킨 콜스택의 호출 정보를 나타내는 문자열이며 디버깅 목적으로 사용한다.
- JS는 7가지의 에러 객체를 생성할 수 있는 Error 생성자 함수를 제공한다.
    - SyntaxError, ReferenceError, TypeError, RangeError, URIError,EvalError.

## throw 문

```jsx
try {
  // 에러 객체를 던지면 catch 코드 블록이 실행되기 시작한다.
  throw new Error('something wrong');
} catch (error) {
  console.log(error);
}
```

- 에러를 발생 시키려면 try 코드 블록에서 throw문으로 에러 객체를 던져야한다.
- 에러를 던지면 catch문의 에러 변수가 생성되고 던져진 에러 객체가 할당된다. 그리고 catch 코드 블록이 실행되기 시작한다.

## 에러의 전파

```jsx
const foo = () => {
  throw Error('foo에서 발생한 에러'); // ④
};

const bar = () => {
  foo(); // ③
};

const baz = () => {
  bar(); // ②
};

try {
  baz(); // ①
} catch (err) {
  console.error(err);
}
```

- 에러는 콜 스택의 아래 방향(실행 중인 실행 컨텍스트가 푸시되기 직전에 푸시된 실행 컨텍스트 방향)으로 전파된다.
- throw된 에러를 캐치하지 않으면 호출자 방향으로 전파된다. 이때 throw 된 에러를 캐치하여 대응하면 프로그램을 강제 종료시키지 않고 코드의 실행 흐름을 복구할 수 있다.
- 주의할 점: 비동기 함수인 setTimeout 또는 프로미스 후속 처리 메서드의 콜백 함수는 호출자가 없다.
    - 이때 콜 스택에 푸시된 콜백 함수의 실행 컨텍스트는 콜스택의 가장 하부에 존재하게 되고, 에러를 전파할 호출자가 존재하지 않아서 에러캐치를 못한다.